<mujoco model="pai_12dof_v2_0605">
  <compiler angle="radian" meshdir="../meshes/" eulerseq="zyx"/>
  <option timestep='0.001' iterations='50' solver='PGS' gravity='0 0 -9.81'>
    <flag sensornoise="enable" frictionloss="enable"/>
  </option>
  <size njmax="500" nconmax="100" />

  <visual>
      <quality shadowsize='4096'/>
      <map znear='0.05'/>
  </visual>
  
  <default>
      <joint limited='true'/>
      <motor ctrllimited='true'/>
      <geom  condim='4' contype="1" conaffinity="15" solref='0.001 2' friction='0.9 0.2 0.2'/>
      <equality solref='0.001 2'/>
      <default class='visualgeom'>
          <geom material='visualgeom' condim='1' contype='0' conaffinity='0'/>
      </default>
      <default class='visualgeom2'>
          <geom material='visualgeom2' condim='1' contype='0' conaffinity='0'/>
      </default>
      <default class='obstacle'>
          <geom material='obstacle' condim='3' contype='1' conaffinity='15'/>
      </default>
  </default>
  <asset>
    <texture type="skybox" builtin="gradient" rgb1="0.3 0.5 0.7" rgb2="0 0 0" width="512" height="512"/>
    <texture name="texplane" type="2d" builtin="checker" rgb1=".2 .3 .4" rgb2=".1 0.15 0.2"
        width="512" height="512" mark="cross" markrgb=".8 .8 .8"/>
    <texture name="texplane2" type="2d" builtin="checker" rgb1="1 0.3137 0.1843" rgb2="0.0 0.30196 0.38039"
        width="512" height="512" mark="cross" markrgb=".8 .8 .8"/>

    <material name="matplane" reflectance="0." texture="texplane" texrepeat="1 1" texuniform="true"/>
    <material name="matplane2" reflectance="0.1" texture="texplane2" texrepeat="1 1" texuniform="true"/>

    <material name='obstacle'  rgba='0.9 0.6 0.2 1'/>
    <material name='visualgeom'  rgba='0.5 0.9 0.2 1'/>
    <material name='visualgeom2'  rgba='0.5 0.9 0.2 1'/>

    <mesh name="base_link" file="base_link.STL"/>
    <mesh name="r_kuan_link" file="r_kuan_link.STL"/>
    <mesh name="r_kuan2_link" file="r_kuan2_link.STL"/>
    <mesh name="r_thigh_link" file="r_thigh_link.STL"/>
    <mesh name="r_calf_link" file="r_calf_link.STL"/>
    <mesh name="r_ankle_link" file="r_ankle_link.STL"/>
    <mesh name="r_foot_link" file="r_foot_link.STL"/>
    <mesh name="l_kuan_link" file="l_kuan_link.STL"/>
    <mesh name="l_kuan2_link" file="l_kuan2_link.STL"/>
    <mesh name="l_thigh_link" file="l_thigh_link.STL"/>
    <mesh name="l_calf_link" file="l_calf_link.STL"/>
    <mesh name="l_ankle_link" file="l_ankle_link.STL"/>
    <mesh name="l_foot_link" file="l_foot_link.STL"/>

    <hfield name='hf0' nrow='200' ncol='200' size="10 5 0.2 .1"/>
  </asset>
  <worldbody>
    <light directional="true" diffuse=".4 .4 .4" specular="0.1 0.1 0.1" pos="0 0 5.0" dir="0 0 -1" castshadow="false"/>
    <light directional="true" diffuse=".6 .6 .6" specular="0.2 0.2 0.2" pos="0 0 4" dir="0 0 -1"/>
    <geom name="ground" type="plane" size="0 0 1" pos="0.001 0 0" quat="1 0 0 0" material="matplane" condim="1" conaffinity='15'/>

    <body name="base_link" pos="0.0 0.0 0.38">
      
      <geom type="mesh" mesh="base_link" group="1" class="visualgeom"/>
      
      <inertial pos="0.0080065 -9.1482E-06 0.03546" mass="1.917" diaginertia="0.0011037 0.0023344 0.0018934" />
      <joint type='slide' axis='1 0 0' limited='false' />
      <joint type='slide' axis='0 1 0' limited='false' />
      <joint type='slide' axis='0 0 1' limited='false' />
      <joint type='ball' limited='false' />
      <site name='imu' size='0.01' pos='0.0 0 0.0'/>  

      <geom type="mesh" contype="0" conaffinity="0" group="1" density="0" rgba="0.75294 0.75294 0.75294 1" mesh="base_link"/>
      <geom type="mesh" rgba="0.75294 0.75294 0.75294 1" mesh="base_link" class="visualgeom"/>
    
      <body name="r_kuan_link" pos="-0.003125 -0.075 -0.009">
        <inertial pos="-0.054431 -6.4382e-05 -0.050511" quat="0.664902 0.746928 -0.00114572 0.00161435" mass="0.44499" diaginertia="0.000174591 0.000111763 0.000106976"/>
        <joint name="r_kuan_joint" pos="0 0 0" axis="0 0 1" range="-3.14 3.14" />
        <geom type="mesh" contype="0" conaffinity="0" group="1" density="0" rgba="0.75294 0.75294 0.75294 1" mesh="r_kuan_link"/>
        <geom type="mesh" rgba="0.75294 0.75294 0.75294 1" mesh="r_kuan_link"/>
        <body name="r_kuan2_link" pos="-0.035 0 -0.056">
          <inertial pos="0.03347 2.0605e-11 -0.0002952" quat="0.706985 -0.0131491 -0.0128225 0.706991" mass="0.81414" diaginertia="0.00034095 0.000205842 0.000204518"/>
          <joint name="r_kuan2_joint" pos="0 0 0" axis="1 0 0" range="-3.14 3.14" />
          <geom type="mesh" contype="0" conaffinity="0" group="1" density="0" rgba="0.75294 0.75294 0.75294 1" mesh="r_kuan2_link"/>
          <geom type="mesh" rgba="0.75294 0.75294 0.75294 1" mesh="r_kuan2_link"/>
          <body name="r_thigh_link" pos="0.035 -0.014 0">
            <inertial pos="0.0067676 0.01505 -0.07154" quat="0.706879 0.0140019 0.0139277 0.707059" mass="0.224" diaginertia="0.000245 0.000236954 1.00471e-05"/>
            <joint name="r_thigh_joint" pos="0 0 0" axis="0 1 0" range="-3.14 3.14" />
            <geom type="mesh" contype="0" conaffinity="0" group="1" density="0" rgba="0.75294 0.75294 0.75294 1" mesh="r_thigh_link"/>
            <geom type="mesh" rgba="0.75294 0.75294 0.75294 1" mesh="r_thigh_link"/>
            <body name="r_calf_link" pos="0.0075 0.028 -0.14981">
              <inertial pos="0.00281593 -0.014 -0.0862394" quat="0.707087 0.00577855 0.00613172 0.707076" mass="0.444943" diaginertia="0.000147777 0.000112981 6.80837e-05"/>
              <joint name="r_calf_joint" pos="0 0 0" axis="0 1 0" range="-3.14 3.14" />
              <geom type="mesh" contype="0" conaffinity="0" group="1" density="0" rgba="0.752941 0.752941 0.752941 1" mesh="r_calf_link"/>
              <geom type="mesh" rgba="0.752941 0.752941 0.752941 1" mesh="r_calf_link"/>
              <body name="r_ankle_link" pos="0 0.001 -0.17495">
                <inertial pos="-1.65092e-07 -0.0150004 1.04243e-08" quat="0.499989 0.500011 0.499989 0.500011" mass="0.00886465" diaginertia="1.00365e-06 9.72625e-07 2.2627e-07"/>
                <joint name="r_ankle_joint" pos="0 0 0" axis="0 1 0" range="-3.14 3.14" />
                <geom type="mesh" contype="0" conaffinity="0" group="1" density="0" rgba="0.898039 0.917647 0.929412 1" mesh="r_ankle_link"/>
                <geom type="mesh" rgba="0.898039 0.917647 0.929412 1" mesh="r_ankle_link"/>
                <body name="r_foot_link" pos="0.015 -0.015 0">
                  <inertial pos="0.0053048 -3.1821e-09 -0.020657" quat="0 0.706752 0 0.707461" mass="0.198" diaginertia="0.00023475 0.00017842 6.22978e-05"/>
                  <joint name="r_foot_joint" pos="0 0 0" axis="1 0 0" range="-3.14 3.14" />
                  <geom type="mesh" contype="0" conaffinity="0" group="1" density="0" rgba="0.75294 0.75294 0.75294 1" mesh="r_foot_link"/>
                  <geom type="mesh" rgba="0.75294 0.75294 0.75294 1" mesh="r_foot_link"/>
                </body>
              </body>
            </body>
          </body>
        </body>
      </body>
      <body name="l_kuan_link" pos="-0.003125 0.075 -0.009">
        <inertial pos="-0.0544311 -6.43822e-05 -0.0505109" quat="0.664929 0.746904 -0.00114577 0.00161428" mass="0.444991" diaginertia="0.000174596 0.000111766 0.000106975"/>
        <joint name="l_kuan_joint" pos="0 0 0" axis="0 0 1" range="-3.14 3.14" />
        <geom type="mesh" contype="0" conaffinity="0" group="1" density="0" rgba="0.752941 0.752941 0.752941 1" mesh="l_kuan_link"/>
        <geom type="mesh" rgba="0.752941 0.752941 0.752941 1" mesh="l_kuan_link"/>
        <body name="l_kuan2_link" pos="-0.035 0 -0.056">
          <inertial pos="0.03347 2.0605e-11 -0.0002952" quat="0.706985 -0.0131491 -0.0128225 0.706991" mass="0.81414" diaginertia="0.00034095 0.000205842 0.000204518"/>
          <joint name="l_kuan2_joint" pos="0 0 0" axis="1 0 0" range="-3.14 3.14" />
          <geom type="mesh" contype="0" conaffinity="0" group="1" density="0" rgba="0.75294 0.75294 0.75294 1" mesh="l_kuan2_link"/>
          <geom type="mesh" rgba="0.75294 0.75294 0.75294 1" mesh="l_kuan2_link"/>
          <body name="l_thigh_link" pos="0.035 0.014 0">
            <inertial pos="0.0067676 -0.01295 -0.07154" quat="0.706879 0.0140019 0.0139277 0.707059" mass="0.224" diaginertia="0.000245 0.000236954 1.00471e-05"/>
            <joint name="l_thigh_joint" pos="0 0 0" axis="0 1 0" range="-3.14 3.14" />
            <geom type="mesh" contype="0" conaffinity="0" group="1" density="0" rgba="0.75294 0.75294 0.75294 1" mesh="l_thigh_link"/>
            <geom type="mesh" rgba="0.75294 0.75294 0.75294 1" mesh="l_thigh_link"/>
            <body name="l_calf_link" pos="0.0075 -0.028 -0.14981">
              <inertial pos="0.0028159 0.014 -0.086239" quat="0.707087 0.00577834 0.00613149 0.707076" mass="0.538" diaginertia="0.00014778 0.000112983 6.80832e-05"/>
              <joint name="l_calf_joint" pos="0 0 0" axis="0 1 0" range="-3.14 3.14" />
              <geom type="mesh" contype="0" conaffinity="0" group="1" density="0" rgba="0.75294 0.75294 0.75294 1" mesh="l_calf_link"/>
              <geom type="mesh" rgba="0.75294 0.75294 0.75294 1" mesh="l_calf_link"/>
              <body name="l_ankle_link" pos="0 -0.001 -0.17495">
                <inertial pos="-1.6509e-07 0.015 1.0424e-08" quat="0.499989 0.500011 0.499989 0.500011" mass="0.0088647" diaginertia="1.0036e-06 9.7263e-07 2.2627e-07"/>
                <joint name="l_ankle_joint" pos="0 0 0" axis="0 1 0" range="-3.14 3.14" />
                <geom type="mesh" contype="0" conaffinity="0" group="1" density="0" rgba="0.89804 0.91765 0.92941 1" mesh="l_ankle_link"/>
                <geom type="mesh" rgba="0.89804 0.91765 0.92941 1" mesh="l_ankle_link"/>
                <body name="l_foot_link" pos="0.015 0.015 0">
                  <inertial pos="0.0053048 -3.1793e-09 -0.020657" quat="0 0.706752 0 0.707461" mass="0.198" diaginertia="0.00023475 0.00017842 6.22978e-05"/>
                  <joint name="l_foot_joint" pos="0 0 0" axis="1 0 0" range="-3.14 3.14" />
                  <geom type="mesh" contype="0" conaffinity="0" group="1" density="0" rgba="0.75294 0.75294 0.75294 1" mesh="l_foot_link"/>
                  <geom type="mesh" rgba="0.75294 0.75294 0.75294 1" mesh="l_foot_link"/>
                </body>
              </body>
            </body>
          </body>
        </body>
      </body>
    </body>
  </worldbody>
  <actuator>
    <motor name="r_kuan_joint" joint="r_kuan_joint" gear="1" ctrllimited="true" ctrlrange="-200 200"/>
    <motor name="r_kuan2_joint" joint="r_kuan2_joint" gear="1" ctrllimited="true" ctrlrange="-200 200"/>
    <motor name="r_thigh_joint" joint="r_thigh_joint" gear="1" ctrllimited="true" ctrlrange="-200 200"/>
    <motor name="r_calf_joint" joint="r_calf_joint" gear="1" ctrllimited="true" ctrlrange="-200 200"/>
    <motor name="r_ankle_joint" joint="r_ankle_joint" gear="1" ctrllimited="true" ctrlrange="-200 200"/>
    <motor name="r_foot_joint" joint="r_foot_joint" gear="1" ctrllimited="true" ctrlrange="-200 200"/>
    <motor name="l_kuan_joint" joint="l_kuan_joint" gear="1" ctrllimited="true" ctrlrange="-200 200"/>
    <motor name="l_kuan2_joint" joint="l_kuan2_joint" gear="1" ctrllimited="true" ctrlrange="-200 200"/>
    <motor name="l_thigh_joint" joint="l_thigh_joint" gear="1" ctrllimited="true" ctrlrange="-200 200"/>
    <motor name="l_calf_joint" joint="l_calf_joint" gear="1" ctrllimited="true" ctrlrange="-200 200"/>
    <motor name="l_ankle_joint" joint="l_ankle_joint" gear="1" ctrllimited="true" ctrlrange="-200 200"/>
    <motor name="l_foot_joint" joint="l_foot_joint" gear="1" ctrllimited="true" ctrlrange="-200 200"/>
  </actuator>

  <sensor>
    <!-- Position sensors -->
    <actuatorpos name="r_kuan_joint_p" actuator="r_kuan_joint" user="13"/>
    <actuatorpos name="r_kuan2_joint_p" actuator="r_kuan2_joint" user="13"/>
    <actuatorpos name="r_thigh_joint_p" actuator="r_thigh_joint" user="13"/>
    <actuatorpos name="r_calf_joint_p" actuator="r_calf_joint" user="13"/>
    <actuatorpos name="r_ankle_joint_p" actuator="r_ankle_joint" user="13"/>
    <actuatorpos name="r_foot_joint_p" actuator="r_foot_joint" user="13"/>
    <actuatorpos name="l_kuan_joint_p" actuator="l_kuan_joint" user="13"/>
    <actuatorpos name="l_kuan2_joint_p" actuator="l_kuan2_joint" user="13"/>
    <actuatorpos name="l_thigh_joint_p" actuator="l_thigh_joint" user="13"/>
    <actuatorpos name="l_calf_joint_p" actuator="l_calf_joint" user="13"/>
    <actuatorpos name="l_ankle_joint_p" actuator="l_ankle_joint" user="13"/>
    <actuatorpos name="l_foot_joint_p" actuator="l_foot_joint" user="13"/>

    <!-- Velocity sensors -->
    <actuatorvel name="r_kuan_joint_v" actuator="r_kuan_joint" user="13" noise="1e-3"/>
    <actuatorvel name="r_kuan2_joint_v" actuator="r_kuan2_joint" user="13" noise="1e-3"/>
    <actuatorvel name="r_thigh_joint_v" actuator="r_thigh_joint" user="13" noise="1e-3"/>
    <actuatorvel name="r_calf_joint_v" actuator="r_calf_joint" user="13" noise="1e-3"/>
    <actuatorvel name="r_ankle_joint_v" actuator="r_ankle_joint" user="13" noise="1e-3"/>
    <actuatorvel name="r_foot_joint_v" actuator="r_foot_joint" user="13" noise="1e-3"/>
    <actuatorvel name="l_kuan_joint_v" actuator="l_kuan_joint" user="13" noise="1e-3"/>
    <actuatorvel name="l_kuan2_joint_v" actuator="l_kuan2_joint" user="13" noise="1e-3"/>
    <actuatorvel name="l_thigh_joint_v" actuator="l_thigh_joint" user="13" noise="1e-3"/>
    <actuatorvel name="l_calf_joint_v" actuator="l_calf_joint" user="13" noise="1e-3"/>
    <actuatorvel name="l_ankle_joint_v" actuator="l_ankle_joint" user="13" noise="1e-3"/>
    <actuatorvel name="l_foot_joint_v" actuator="l_foot_joint" user="13" noise="1e-3"/>

    <!-- Force sensors -->
    <actuatorfrc name="r_kuan_joint_f" actuator="r_kuan_joint" user="13" noise="1e-3"/>
    <actuatorfrc name="r_kuan2_joint_f" actuator="r_kuan2_joint" user="13" noise="1e-3"/>
    <actuatorfrc name="r_thigh_joint_f" actuator="r_thigh_joint" user="13" noise="1e-3"/>
    <actuatorfrc name="r_calf_joint_f" actuator="r_calf_joint" user="13" noise="1e-3"/>
    <actuatorfrc name="r_ankle_joint_f" actuator="r_ankle_joint" user="13" noise="1e-3"/>
    <actuatorfrc name="r_foot_joint_f" actuator="r_foot_joint" user="13" noise="1e-3"/>
    <actuatorfrc name="l_kuan_joint_f" actuator="l_kuan_joint" user="13" noise="1e-3"/>
    <actuatorfrc name="l_kuan2_joint_f" actuator="l_kuan2_joint" user="13" noise="1e-3"/>
    <actuatorfrc name="l_thigh_joint_f" actuator="l_thigh_joint" user="13" noise="1e-3"/>
    <actuatorfrc name="l_calf_joint_f" actuator="l_calf_joint" user="13" noise="1e-3"/>
    <actuatorfrc name="l_ankle_joint_f" actuator="l_ankle_joint" user="13" noise="1e-3"/>
    <actuatorfrc name="l_foot_joint_f" actuator="l_foot_joint" user="13" noise="1e-3"/>
  
    <framequat     name='orientation' objtype='site' noise='0.001' objname='imu'/>
    <framepos     name='position' objtype='site' noise='0.001' objname='imu'/>
    <gyro          name='angular-velocity'    site='imu' noise='0.005' cutoff='34.9'/>
    <velocimeter   name='linear-velocity'     site='imu' noise='0.001' cutoff='30'/>
    <accelerometer name='linear-acceleration' site='imu' noise='0.005' cutoff='157'/>
    <magnetometer  name='magnetometer'        site='imu'/>
  
  </sensor>
</mujoco>
