<?xml version="1.0" encoding="utf-8"?>
<!-- This URDF was automatically created by SolidWorks to URDF Exporter! Originally created by Stephen Brawner (brawner@gmail.com) 
     Commit Version: 1.6.0-4-g7f85cfe  Build Version: 1.6.7995.38578
     For more information, please see http://wiki.ros.org/sw_urdf_exporter -->
  
<robot
  name="pai_12dof_v2_0605">
  <mujoco>
    <compiler 
      meshdir="../meshes/" 
      balanceinertia="true" 
      discardvisual="false" />
  </mujoco>
  <link
    name="base_link">
    <inertial>
      <origin
        xyz="0.0080065 -9.1482E-06 0.03546"
        rpy="0 0 0" />
      <mass
        value="1.917" />
      <inertia
        ixx="0.0011037"
        ixy="6.7319E-07"
        ixz="-0.00010863"
        iyy="0.0023344"
        iyz="-1.8481E-06"
        izz="0.0018934" />
    </inertial>
    <visual>
      <origin
        xyz="0 0 0"
        rpy="0 0 0" />
      <geometry>
        <mesh
          filename="../meshes/base_link.STL" />
      </geometry>
      <material
        name="">
        <color
          rgba="0.75294 0.75294 0.75294 1" />
      </material>
    </visual>
    <collision>
      <origin
        xyz="0 0 0"
        rpy="0 0 0" />
      <geometry>
        <mesh
          filename="../meshes/base_link.STL" />
      </geometry>
    </collision>
  </link>
  <link
    name="r_kuan_link">
    <inertial>
      <origin
        xyz="-0.054431 -6.4382E-05 -0.050511"
        rpy="0 0 0" />
      <mass
        value="0.44499" />
      <inertia
        ixx="0.00017459"
        ixy="3.1567E-08"
        ixz="2.4773E-07"
        iyy="0.00010704"
        iyz="-5.5057E-07"
        izz="0.0001117" />
    </inertial>
    <visual>
      <origin
        xyz="0 0 0"
        rpy="0 0 0" />
      <geometry>
        <mesh
          filename="../meshes/r_kuan_link.STL" />
      </geometry>
      <material
        name="">
        <color
          rgba="0.75294 0.75294 0.75294 1" />
      </material>
    </visual>
    <collision>
      <origin
        xyz="0 0 0"
        rpy="0 0 0" />
      <geometry>
        <mesh
          filename="../meshes/r_kuan_link.STL" />
      </geometry>
    </collision>
  </link>
  <joint
    name="r_kuan_joint"
    type="revolute">
    <origin
      xyz="-0.003125 -0.075 -0.009"
      rpy="0 0 0" />
    <parent
      link="base_link" />
    <child
      link="r_kuan_link" />
    <axis
      xyz="0 0 1" />
    <limit
      lower="-3.14"
      upper="3.14"
      effort="21"
      velocity="21" />
  </joint>
  <link
    name="r_kuan2_link">
    <inertial>
      <origin
        xyz="0.03347 2.0605E-11 -0.0002952"
        rpy="0 0 0" />
      <mass
        value="0.81414" />
      <inertia
        ixx="0.00020584"
        ixy="1.0943E-12"
        ixz="4.8574E-08"
        iyy="0.00034095"
        iyz="-6.3036E-08"
        izz="0.00020452" />
    </inertial>
    <visual>
      <origin
        xyz="0 0 0"
        rpy="0 0 0" />
      <geometry>
        <mesh
          filename="../meshes/r_kuan2_link.STL" />
      </geometry>
      <material
        name="">
        <color
          rgba="0.75294 0.75294 0.75294 1" />
      </material>
    </visual>
    <collision>
      <origin
        xyz="0 0 0"
        rpy="0 0 0" />
      <geometry>
        <mesh
          filename="../meshes/r_kuan2_link.STL" />
      </geometry>
    </collision>
  </link>
  <joint
    name="r_kuan2_joint"
    type="revolute">
    <origin
      xyz="-0.035 0 -0.056"
      rpy="0 0 0" />
    <parent
      link="r_kuan_link" />
    <child
      link="r_kuan2_link" />
    <axis
      xyz="1 0 0" />
    <limit
      lower="-3.14"
      upper="3.14"
      effort="21"
      velocity="21" />
  </joint>
  <link
    name="r_thigh_link">
    <inertial>
      <origin
        xyz="0.0067676 0.01505 -0.07154"
        rpy="0 0 0" />
      <mass
        value="0.224" />
      <inertia
        ixx="0.0002366"
        ixy="-1.1282E-09"
        ixz="-8.9537E-06"
        iyy="0.000245"
        iyz="2.3544E-08"
        izz="1.0401E-05" />
    </inertial>
    <visual>
      <origin
        xyz="0 0 0"
        rpy="0 0 0" />
      <geometry>
        <mesh
          filename="../meshes/r_thigh_link.STL" />
      </geometry>
      <material
        name="">
        <color
          rgba="0.75294 0.75294 0.75294 1" />
      </material>
    </visual>
    <collision>
      <origin
        xyz="0 0 0"
        rpy="0 0 0" />
      <geometry>
        <mesh
          filename="../meshes/r_thigh_link.STL" />
      </geometry>
    </collision>
  </link>
  <joint
    name="r_thigh_joint"
    type="revolute">
    <origin
      xyz="0.035 -0.014 0"
      rpy="0 0 0" />
    <parent
      link="r_kuan2_link" />
    <child
      link="r_thigh_link" />
    <axis
      xyz="0 1 0" />
    <limit
      lower="-3.14"
      upper="3.14"
      effort="21"
      velocity="21" />
  </joint>
  <link
    name="r_calf_link">
    <inertial>
      <origin
        xyz="0.00281593480178935 -0.0139999969604586 -0.086239436981651"
        rpy="0 0 0" />
      <mass
        value="0.444942664885023" />
      <inertia
        ixx="0.000112968661576375"
        ixy="-6.14771331738193E-12"
        ixz="-7.56107054802247E-07"
        iyy="0.000147776607396975"
        iyz="-3.9796891718758E-08"
        izz="6.80964863575587E-05" />
    </inertial>
    <visual>
      <origin
        xyz="0 0 0"
        rpy="0 0 0" />
      <geometry>
        <mesh
          filename="../meshes/r_calf_link.STL" />
      </geometry>
      <material
        name="">
        <color
          rgba="0.752941176470588 0.752941176470588 0.752941176470588 1" />
      </material>
    </visual>
    <collision>
      <origin
        xyz="0 0 0"
        rpy="0 0 0" />
      <geometry>
        <mesh
          filename="../meshes/r_calf_link.STL" />
      </geometry>
    </collision>
  </link>
  <joint
    name="r_calf_joint"
    type="revolute">
    <origin
      xyz="0.0075 0.028 -0.14981"
      rpy="0 0 0" />
    <parent
      link="r_thigh_link" />
    <child
      link="r_calf_link" />
    <axis
      xyz="0 1 0" />
    <limit
      lower="-3.14"
      upper="3.14"
      effort="21"
      velocity="21" />
  </joint>
  <link
    name="r_ankle_link">
    <inertial>
      <origin
        xyz="-1.6509198083603E-07 -0.0150003545428527 1.04242601217663E-08"
        rpy="0 0 0" />
      <mass
        value="0.00886465357060087" />
      <inertia
        ixx="2.26270093875981E-07"
        ixy="8.25154855032966E-14"
        ixz="-8.86876893021843E-13"
        iyy="1.00364671071319E-06"
        iyz="1.33615017437302E-12"
        izz="9.72625201373387E-07" />
    </inertial>
    <visual>
      <origin
        xyz="0 0 0"
        rpy="0 0 0" />
      <geometry>
        <mesh
          filename="../meshes/r_ankle_link.STL" />
      </geometry>
      <material
        name="">
        <color
          rgba="0.898039215686275 0.917647058823529 0.929411764705882 1" />
      </material>
    </visual>
    <collision>
      <origin
        xyz="0 0 0"
        rpy="0 0 0" />
      <geometry>
        <mesh
          filename="../meshes/r_ankle_link.STL" />
      </geometry>
    </collision>
  </link>
  <joint
    name="r_ankle_joint"
    type="revolute">
    <origin
      xyz="0 0.001 -0.17495"
      rpy="0 0 0" />
    <parent
      link="r_calf_link" />
    <child
      link="r_ankle_link" />
    <axis
      xyz="0 1 0" />
    <limit
      lower="-3.14"
      upper="3.14"
      effort="21"
      velocity="21" />
  </joint>
  <link
    name="r_foot_link">
    <inertial>
      <origin
        xyz="0.0053048 -3.1821E-09 -0.020657"
        rpy="0 0 0" />
      <mass
        value="0.198" />
      <inertia
        ixx="6.2298E-05"
        ixy="2.0233E-12"
        ixz="-1.7282E-07"
        iyy="0.00017842"
        iyz="-2.034E-12"
        izz="0.00023475" />
    </inertial>
    <visual>
      <origin
        xyz="0 0 0"
        rpy="0 0 0" />
      <geometry>
        <mesh
          filename="../meshes/r_foot_link.STL" />
      </geometry>
      <material
        name="">
        <color
          rgba="0.75294 0.75294 0.75294 1" />
      </material>
    </visual>
    <collision>
      <origin
        xyz="0 0 0"
        rpy="0 0 0" />
      <geometry>
        <mesh
          filename="../meshes/r_foot_link.STL" />
      </geometry>
    </collision>
  </link>
  <joint
    name="r_foot_joint"
    type="revolute">
    <origin
      xyz="0.015 -0.015 0"
      rpy="0 0 0" />
    <parent
      link="r_ankle_link" />
    <child
      link="r_foot_link" />
    <axis
      xyz="1 0 0" />
    <limit
      lower="-3.14"
      upper="3.14"
      effort="21"
      velocity="21" />
  </joint>
  <link
    name="l_kuan_link">
    <inertial>
      <origin
        xyz="-0.0544310574714842 -6.43821739947786E-05 -0.0505108585839627"
        rpy="0 0 0" />
      <mass
        value="0.444991449767726" />
      <inertia
        ixx="0.000174594670384385"
        ixy="3.15673595832876E-08"
        ixz="2.47734615065989E-07"
        iyy="0.000107039429721536"
        iyz="-5.50574561862803E-07"
        izz="0.000111702464628443" />
    </inertial>
    <visual>
      <origin
        xyz="0 0 0"
        rpy="0 0 0" />
      <geometry>
        <mesh
          filename="../meshes/l_kuan_link.STL" />
      </geometry>
      <material
        name="">
        <color
          rgba="0.752941176470588 0.752941176470588 0.752941176470588 1" />
      </material>
    </visual>
    <collision>
      <origin
        xyz="0 0 0"
        rpy="0 0 0" />
      <geometry>
        <mesh
          filename="../meshes/l_kuan_link.STL" />
      </geometry>
    </collision>
  </link>
  <joint
    name="l_kuan_joint"
    type="revolute">
    <origin
      xyz="-0.003125 0.075 -0.009"
      rpy="0 0 0" />
    <parent
      link="base_link" />
    <child
      link="l_kuan_link" />
    <axis
      xyz="0 0 1" />
    <limit
      lower="-3.14"
      upper="3.14"
      effort="21"
      velocity="21" />
  </joint>
  <link
    name="l_kuan2_link">
    <inertial>
      <origin
        xyz="0.03347 2.0605E-11 -0.0002952"
        rpy="0 0 0" />
      <mass
        value="0.81414" />
      <inertia
        ixx="0.00020584"
        ixy="1.0943E-12"
        ixz="4.8574E-08"
        iyy="0.00034095"
        iyz="-6.3036E-08"
        izz="0.00020452" />
    </inertial>
    <visual>
      <origin
        xyz="0 0 0"
        rpy="0 0 0" />
      <geometry>
        <mesh
          filename="../meshes/l_kuan2_link.STL" />
      </geometry>
      <material
        name="">
        <color
          rgba="0.75294 0.75294 0.75294 1" />
      </material>
    </visual>
    <collision>
      <origin
        xyz="0 0 0"
        rpy="0 0 0" />
      <geometry>
        <mesh
          filename="../meshes/l_kuan2_link.STL" />
      </geometry>
    </collision>
  </link>
  <joint
    name="l_kuan2_joint"
    type="revolute">
    <origin
      xyz="-0.035 0 -0.056"
      rpy="0 0 0" />
    <parent
      link="l_kuan_link" />
    <child
      link="l_kuan2_link" />
    <axis
      xyz="1 0 0" />
    <limit
      lower="-3.14"
      upper="3.14"
      effort="21"
      velocity="21" />
  </joint>
  <link
    name="l_thigh_link">
    <inertial>
      <origin
        xyz="0.0067676 -0.01295 -0.07154"
        rpy="0 0 0" />
      <mass
        value="0.224" />
      <inertia
        ixx="0.0002366"
        ixy="-1.1282E-09"
        ixz="-8.9537E-06"
        iyy="0.000245"
        iyz="2.3544E-08"
        izz="1.0401E-05" />
    </inertial>
    <visual>
      <origin
        xyz="0 0 0"
        rpy="0 0 0" />
      <geometry>
        <mesh
          filename="../meshes/l_thigh_link.STL" />
      </geometry>
      <material
        name="">
        <color
          rgba="0.75294 0.75294 0.75294 1" />
      </material>
    </visual>
    <collision>
      <origin
        xyz="0 0 0"
        rpy="0 0 0" />
      <geometry>
        <mesh
          filename="../meshes/l_thigh_link.STL" />
      </geometry>
    </collision>
  </link>
  <joint
    name="l_thigh_joint"
    type="revolute">
    <origin
      xyz="0.035 0.014 0"
      rpy="0 0 0" />
    <parent
      link="l_kuan2_link" />
    <child
      link="l_thigh_link" />
    <axis
      xyz="0 1 0" />
    <limit
      lower="-3.14"
      upper="3.14"
      effort="21"
      velocity="21" />
  </joint>
  <link
    name="l_calf_link">
    <inertial>
      <origin
        xyz="0.0028159 0.014 -0.086239"
        rpy="0 0 0" />
      <mass
        value="0.538" />
      <inertia
        ixx="0.00011297"
        ixy="-6.1477E-12"
        ixz="-7.5611E-07"
        iyy="0.00014778"
        iyz="-3.9797E-08"
        izz="6.8096E-05" />
    </inertial>
    <visual>
      <origin
        xyz="0 0 0"
        rpy="0 0 0" />
      <geometry>
        <mesh
          filename="../meshes/l_calf_link.STL" />
      </geometry>
      <material
        name="">
        <color
          rgba="0.75294 0.75294 0.75294 1" />
      </material>
    </visual>
    <collision>
      <origin
        xyz="0 0 0"
        rpy="0 0 0" />
      <geometry>
        <mesh
          filename="../meshes/l_calf_link.STL" />
      </geometry>
    </collision>
  </link>
  <joint
    name="l_calf_joint"
    type="revolute">
    <origin
      xyz="0.0075 -0.028 -0.14981"
      rpy="0 0 0" />
    <parent
      link="l_thigh_link" />
    <child
      link="l_calf_link" />
    <axis
      xyz="0 1 0" />
    <limit
      lower="-3.14"
      upper="3.14"
      effort="21"
      velocity="21" />
  </joint>
  <link
    name="l_ankle_link">
    <inertial>
      <origin
        xyz="-1.6509E-07 0.015 1.0424E-08"
        rpy="0 0 0" />
      <mass
        value="0.0088647" />
      <inertia
        ixx="2.2627E-07"
        ixy="8.2515E-14"
        ixz="-8.8688E-13"
        iyy="1.0036E-06"
        iyz="1.3362E-12"
        izz="9.7263E-07" />
    </inertial>
    <visual>
      <origin
        xyz="0 0 0"
        rpy="0 0 0" />
      <geometry>
        <mesh
          filename="../meshes/l_ankle_link.STL" />
      </geometry>
      <material
        name="">
        <color
          rgba="0.89804 0.91765 0.92941 1" />
      </material>
    </visual>
    <collision>
      <origin
        xyz="0 0 0"
        rpy="0 0 0" />
      <geometry>
        <mesh
          filename="../meshes/l_ankle_link.STL" />
      </geometry>
    </collision>
  </link>
  <joint
    name="l_ankle_joint"
    type="revolute">
    <origin
      xyz="0 -0.001 -0.17495"
      rpy="0 0 0" />
    <parent
      link="l_calf_link" />
    <child
      link="l_ankle_link" />
    <axis
      xyz="0 1 0" />
    <limit
      lower="-3.14"
      upper="3.14"
      effort="21"
      velocity="21" />
  </joint>
  <link
    name="l_foot_link">
    <inertial>
      <origin
        xyz="0.0053048 -3.1793E-09 -0.020657"
        rpy="0 0 0" />
      <mass
        value="0.198" />
      <inertia
        ixx="6.2298E-05"
        ixy="2.0201E-12"
        ixz="-1.7282E-07"
        iyy="0.00017842"
        iyz="-2.0241E-12"
        izz="0.00023475" />
    </inertial>
    <visual>
      <origin
        xyz="0 0 0"
        rpy="0 0 0" />
      <geometry>
        <mesh
          filename="../meshes/l_foot_link.STL" />
      </geometry>
      <material
        name="">
        <color
          rgba="0.75294 0.75294 0.75294 1" />
      </material>
    </visual>
    <collision>
      <origin
        xyz="0 0 0"
        rpy="0 0 0" />
      <geometry>
        <mesh
          filename="../meshes/l_foot_link.STL" />
      </geometry>
    </collision>
  </link>
  <joint
    name="l_foot_joint"
    type="revolute">
    <origin
      xyz="0.015 0.015 0"
      rpy="0 0 0" />
    <parent
      link="l_ankle_link" />
    <child
      link="l_foot_link" />
    <axis
      xyz="1 0 0" />
    <limit
      lower="-3.14"
      upper="3.14"
      effort="21"
      velocity="21" />
  </joint>
</robot>